# 예외 처리

JavaScript에는 코드 실행 중에 예기치 못한 에러가 발생했을 때, 이로부터 코드의 실행 흐름을 복구할 수 있는 기능이 내장되어 있습니다. 이런 기능을 일러 **예외 처리(exception handling)**라고 합니다.

## 동기식 코드에서의 예외 처리

JavaScript 코드에서 발생할 수 있는 에러에는 다양한 것들이 있습니다. 문법 에러와 같이 프로그래머의 실수로 인해 에러가 발생하는 경우도 있지만, 네트워크 에러와 같이 코드와는 무관한 이유로 발생하는 에러도 있습니다.

```js
new Array(-1); // RangeError: Invalid array length
```

```js
console.log(foo); // ReferenceError: foo is not defined
fetch('https://nonexistent-domain.nowhere'); // TypeError: Failed to fetch
```

코드 실행 중에 에러가 발생하면, **코드의 실행이 중단되어 그 시점에 실행 중이었던 작업을 완료할 수 없게 됩니다.** JavaScript는 이로부터 **코드의 실행 흐름을 원상복구**할 수 있는 기능을 제공하며, `try...catch...finally` 구문을 사용하면 에러가 나더라도 코드의 실행을 지속할 수 있습니다.

```js
try {
  console.log('에러가 나기 직전까지의 코드는 잘 실행됩니다.');
  new Array(-1); // RangeError: Invalid array length
  console.log('에러가 난 이후의 코드는 실행되지 않습니다.');
} catch (error) {
  console.log('코드의 실행 흐름이 catch 블록으로 옮겨집니다.');
  console.log(`다음과 같은 에러가 발생했습니다: ${error.name}: ${error.message}`);
}
```

```js
try {
  console.log('에러가 나기 직전까지의 코드는 잘 실행됩니다.');
  new Array(-1); // RangeError: Invalid array length
  console.log(foo);
  console.log('에러가 난 이후의 코드는 실행되지 않습니다.');
} catch (e) {
    if(e.name === 'rangeerror'){
        alert('배열 생성자에 잘못된 인수가 입력되었습니다.')
    }
    else if(e.name === 'referenceerror'){
        console.log(`다음과 같은 에러가 발생했습니다: ${error.name}: ${error.message}`);
    }
  console.log('코드의 실행 흐름이 catch 블록으로 옮겨집니다.');
}
```

> 여러 error에 대한 처리를 같이 할 수 있다. 먼저 실행된 error가 먼저 실행

에러가 났을 때 원상복구를 시도할 코드를 `try` 블록 내부에 작성하면, 에러가 발생했을 때 코드의 실행 흐름이 `try` 블록에서 `catch` 블록으로 옮겨갑니다. 이 때, `catch` 블록 안에서는 에러에 대한 정보를 담고 있는 객체(위 코드의 `e`)를 사용할 수 있습니다.

`try` 블록은 예외 처리를 위해서만 쓰이는 것은 아닙니다. `try` 블록 바로 뒤에 `finally` 블록이 오면, `finally` 블록에 있는 코드는 `try` 블록 안에서의 에러 발생 여부와 관계 없이 **무조건 실행됩니다.** 심지어 `try` 블록 내에서 `return`, `break`, `continue` 등으로 인해 **코드의 실행 흐름이 즉시 이동될 때에도 마찬가지**입니다.

```js
for (let i of [1, 2, 3]) {
  try {
    if (i === 3) {
      break;
    }
  } finally {
    console.log(`현재 i의 값: ${i}`);
  }
}
```

`finally` 블록은 `catch` 블록과도 같이 사용됩니다. 이 때 코드의 실행 순서를 정리해 보면 다음과 같습니다.

- 에러가 안 났을 때: `try` - `finally`
- 에러가 났을 때: `try` - **에러 발생** - `catch` - `finally`

아래 코드를 통해 코드의 실행 순서를 시험해보세요.

```js
try {
  console.log('try');
  new Array(-1); // RangeError: Invalid array length
} catch (e) {
  console.log('catch');
} finally {
  console.log('finally');
}
```



## 직접 에러 발생시키기

`Error` 생성자와 `throw` 구문을 사용해서 프로그래머가 직접 에러를 발생시킬 수 있습니다.

```js
const even = parseInt(prompt('짝수를 입력하세요'));
if (even % 2 !== 0) {
  throw new Error('짝수가 아닙니다.');
}
```

간혹 프로그램을 작성하면서 **에러의 종류를 구분**해야 하거나 **에러 객체에 기능을 추가**해야 할 필요가 있습니다. 이런 경우에는 **Error를 상속받는 클래스**를 만들어서, `throw` 구문에서 이 클래스를 대신 사용할 수 있습니다.

예를 들어, 아래 `MyError` 클래스를 통해 에러 객체를 생성할 때 에러에 대한 상세 정보를 포함시키면, `catch` 블록 안에서 원상복구를 위해 이 값을 활용할 수 있습니다.

```js
class MyError extends Error {
  constructor(value, ...params) {
    super(...params);
    this.value = value;
    this.name = 'MyError';
  }
}

try {
  const even = parseInt(prompt('짝수를 입력하세요'));
  if (even % 2 !== 0) {
    throw new MyError(even, '짝수가 아닙니다.');
  }
} catch (e) {
  if (e instanceof MyError) {
    console.log(e.value);
  }
}
```

## 비동기식 코드에서의 예외 처리

 > **비동기 콜백**
> 호출 스택에서 바로 실행되는 것이 아니라 브라우저의 작업큐에 들어갔다가 실행된다

**비동기식으로 작동하는 콜백**의 **내부**에서 발생한 에러는, **콜백 바깥**에 있는 `try` 블록으로는 잡아낼 수 없습니다.

```js
try {
  setTimeout(() => {
    throw new Error('에러!');
  });
} catch (e) {
  console.error(e);
}
```

JavaScript 엔진은 에러가 발생하는 순간 **호출 스택을 되감는 과정**을 거칩니다. **이 과정 중에 try블록을 만나야** 코드의 실행 흐름을 원상복구시킬 수 있습니다. 위 예제에서 `setTimeout`에 넘겨진 콜백에서 에러가 발생하면, 호출 스택을 따라 올라가도 `try` 블록을 만나는 것이 아니므로, 코드의 실행 흐름이 `catch` 블록으로 옮겨지지 않는 것입니다.

> 비동기는 호출스택이 모두 비워져야 실행되는데 try, catch는 호출스택안에서의 에러만
> 처리할수 있음으로 비동기 처리 구문에서의 에러를 잡아 낼수 없다.

따라서, 위 예제의 `try` 블록을 비동기 콜백 내부에 작성해주어야 합니다.

```js
setTimeout(() => {
  try {
    throw new Error('에러!');
  } catch (e) {
    console.error(e);
  }
});
```
> 비동기식 코드에서의 예외처리 방식과 비동기식 함수의 예외처리 방식은 완전히 다르다.

### Promise

Promise 객체는 세 가지 상태를 가질 수 있습니다.

- pending - Promise 객체에 결과값이 채워지지 않은 상태
- fulfilled - Promise 객체에 결과값이 채워진 상태
- **rejected - Promise 객체에 결과값을 채우려고 시도하다가 에러가 난 상태**

Promise 객체가 rejected 상태가 되면, 이 Promise에 대해서는 `then` 메소드에 첫 번째 인수로 넘겨준 콜백이 실행되지 않고, **두 번째 인수로 넘겨준 콜백**이 대신 실행됩니다. 그리고 이 콜백에는 **에러 객체가 첫 번째 인수**로 주어집니다.

```js
const p = new Promise(resolve => {
  const even = parseInt(prompt('짝수를 입력하세요'));
  if (even % 2 !== 0) {
    throw new Error('짝수가 아닙니다.');
  } else {
    resolve(even);
  }
});

p.then(even => {
  return '짝수입니다.';
}, e => {
  return e.message;
}).then(alert);
```

혹은, **catch 메소드**를 통해 에러 처리 콜백을 지정해줄 수도 있습니다.

```js
p.then(even => {
  return '짝수입니다.';
}).catch(e => {
  return e.message;
}).then(alert);
```

만약, `then` 메소드의 연쇄 안에서 에러가 발생하면, `try...catch` 구문과 유사하게 **처음 만나는 에러 처리 콜백으로 코드의 실행 흐름이 건너뛰는 결과**를 낳게 됩니다.

```js
Promise.resolve()
  .then(() => {
    throw new Error('catch 메소드를 통해 예외 처리를 할 수 있습니다.');
  })
  .then(() => {
    console.log('이 코드는 실행되지 않습니다.');
  })
  .catch(e => {
    return e.message;
  })
  .then(console.log);
```

### 비동기 함수

앞에서 봤던 Promise 객체의 예외 처리 방식은, 일반적인 동기식 예외 처리 방식과 다르게 **콜백**을 사용하고 있어서 코드를 복잡하게 만드는 원인이 됩니다.

비동기 함수 내부에서는, **rejected 상태가 된 Promise 객체**를 동기식 예외 처리 방식과 동일하게 **try...catch...finally 구문으로 처리할 수 있습니다.**

```js
async function func() {
  try {
    const res = await fetch('https://nonexistent-domain.nowhere');
  } catch (e) {
    console.log(e.message);
  }
}

func(); // 출력 결과: Failed to fetch
```

단, Promise 객체에 대해 **await 구문**을 사용하지 않는 경우, 에러가 발생해도 `catch` 블록으로 코드의 실행 흐름이 이동하지 않는다는 사실을 기억하세요.

```js
async function func() {
  try {
    fetch('https://nonexistent-domain.nowhere');
  } catch (e) {
    console.log(e.message);
  }
}

func(); // 아무것도 출력되지 않습니다.
```

# 모듈

최근들어 프론트엔드 프로젝트의 규모가 커짐에 따라, JavaScript 코드를 여러 파일과 폴더에 나누어 작성하고 서로가 서로를 효율적으로 불러올 수 있도록 해주는 시스템의 필요성이 절실해졌습니다. 이에 따라 모듈 시스템이 ES2015에 추가되었습니다.

ES2015 모듈은 최근에 (Chrome 61, FF 60, SF 10.1) 브라우저에서 사용할 수 있게 되었습니다. `script` 태그에 `type="module"` 어트리뷰트를 추가해주면, 이 파일은 모듈로서 동작합니다. 파일 확장자로는 대개 `mjs`가 사용됩니다.

```js
<script type="module" src="index.mjs"></script>
```

다만 모듈은 이전까지의 JavaScript 파일의 동작방식과는 다른 동작방식을 가지고 있고, 모듈이 제대로 동작하려면 [몇 가지 조건](https://jakearchibald.com/2017/es-modules-in-browsers/)을 충족시켜야 해서 사용법이 복잡하며, 구형 브라우저는 모듈을 지원하지 않는다는 문제가 있어 아직은 브라우저에 내장된 모듈 기능을 사용하는 경우가 많지 않습니다. 대신 Webpack, Parcel 등의 **모듈 번들러**를 통해 변환과정을 거친 뒤, 브라우저에는 일반적인 JavaScript 파일로서 불러오는 방법이 널리 사용되고 있는 추세입니다.

## 모듈이란?

ES2015 모듈은 기본적으로 JavaScript 코드를 담고 있는 파일입니다. 다만 일반적인 JavaScript 파일과는 다른 여러가지 차이점을 갖고 있습니다.

- `import` 혹은 `export` 구문을 사용할 수 있습니다.
- 별다른 처리를 해주지 않아도 엄격 모드(strict mode)로 동작합니다.
- 모듈의 가장 바깥쪽에서 선언된 이름은 전역 스코프가 아니라 **모듈 스코프**에서 선언됩니다.

## 모듈 스코프

모듈 내부의 가장 바깥 스코프에서 이름을 선언하더라도, 전역 스코프가 아니라 **모듈 스코프**에서 선언됩니다.

```js
// variables.js

var foo = 'bar';

// 이 파일이 모듈로서 사용되고 있다면, `undefined`가 출력됩니다.
console.log(window.foo);
```

따라서 여러 모듈의 가장 바깥쪽에서 같은 이름으로 변수, 함수, 클래스를 선언하더라도, 서로 다른 스코프에서 선언되기 때문에 이름의 충돌이 생길 일이 없습니다.

## export & import

모듈 스코프에서 정의된 이름은 `export` 구문을 통해 다른 파일에서 사용할 수 있습니다.

```js
// variables.js
const foo = 'bar';
const spam = 'eggs';

// foo, spam을 다른 파일에서 사용할 수 있도록 export 해주었습니다.
export { foo, spam };
```

위에서 `export`된 이름을 다른 파일에서 `import` 구문을 통해 가져온 뒤 사용할 수 있습니다.

```js
// main.js

// variables 모듈에 선언된 이름을 사용하기 위해 import 해주었습니다.
import { foo, spam } from './variables.js';

console.log(foo);
console.log(spam);
```

단순히 값을 저장하고 있는 변수뿐만 아니라, 함수나 클래스도 `export`를 통해 여러 모듈에서 재사용할 수 있습니다.

```js
// functions.js

function add(x, y) {
  return x + y;
}

class Person {
  // ...
}

export { add, Person };
```

다른 모듈에 있는 이름을 사용하려면, 반드시 해당 모듈에서 이름을 `export` 해주어야 합니다. `export` 해주지 않은 이름을 다른 모듈에서 `import` 하면 의도대로 동작하지 않습니다. (모듈 실행 환경에 따라 에러가 날 수도 있고, 이름에 `undefined`가 들어있을 수도 있습니다.)

```js
// variables.js

const foo = 'bar'
// main.js
import { foo } from './variables.js';

console.log(foo); // 에러가 나거나, `undefined`가 출력됨
```

app 컴포넌트에는 상태 변경에 대한 코드만, UI를 담당하는 컴포넌트에는 그에 맞는 동작 코드작성

중괄호`{ }`안에는 하나의 react component만 반환해야 한다.

- -> React.Fragment

  여러 react component를 쓸수 있게 해주는 component

